Workbook
Name AMS: Mapping!$N$4:$N$13
Name MYS_Fractioned: Input_MYS_Adj!$A$1:$AB$33

Sheet Comparison
A1: Country | B1: Indonesia | H1: Notes:
A2: Variable | B2: Existing Capacity | H2: Vietnam data is not fixed yet
A3: N Technology | B3: {=_xlfn.LET(_xlpm.val,_xlfn._xlws.FILTER(_xlfn.HSTACK(leap[Branch Path],leap[[2005]:[2024]]),(leap[Region]=B1)*(leap[Variable]=B2)),ROWS(_xlfn._xlws.FILTER(_xlfn.TAKE(_xlpm.val,,1),_xlfn.BYROW(_xlfn.DROP(_xlpm.val,,1),_xleta.SUM)>0)))} -> 14
A5: Data | H5: Comparison
B6: LEAP | D6: EBT | I6: LEAP | K6: EBT
A7: Year | B7: Fuel | C7: Value | D7: Fuel | E7: Value | F7: ∆ | H7: Year | I7: Fuel | J7: Value | K7: Fuel | L7: Value
A8: {=_xlfn.CEILING.MATH(_xlfn.SEQUENCE(B3*(2024-2005+1))/B3,1)-1+2005} -> 2005 | B8: {=_xlfn.LET(_xlpm.country,B1, _xlpm.len,_xlfn.TOCOL((2024-2005+1)*B3), _xlpm.val,_xlfn._xlws.FILTER(_xlfn.HSTACK(leap[Branch Path],leap[[2005]:[2024]]),(leap[Region]=B1)*(leap[Variable]=B2)), _xlpm.fval,_xlfn._xlws.FILTER(_xlpm.val,_xlfn.BYROW(_xlfn.DROP(_xlpm.val,,1),_xleta.SUM)>0), _xlpm.fuel,_xlfn.TEXTAFTER(_xlfn.TAKE(_xlpm.fval,,1),"\",3), _xlpm.r,2024-2005+1,_xlpm.l,B3, _xlpm.fuel_seq,_xlfn.TOCOL(IF(_xlfn.SEQUENCE(,_xlpm.r)<=_xlfn.CEILING.MATH(_xlfn.SEQUENCE(_xlpm.l)/_xlpm.l,1)-1+_xlpm.r,_xlpm.fuel,NA()),,1), _xlpm.fuel_val,_xlfn.TOCOL(_xlfn.DROP(_xlpm.fval,,1),,1), _xlfn.HSTACK(_xlpm.fuel_seq,_xlpm.fuel_val))} -> Coal Subcritical | C8: 9750 | D8: {=_xlfn.LET(_xlpm.country,B1, _xlpm.table,INDIRECT(IF(B2="Existing Capacity",_xlpm.country,_xlpm.country&"_HP")), _xlpm.len,_xlfn.TOCOL((2024-2005+1)*B3), _xlpm.val,_xlfn._xlws.FILTER(_xlfn.HSTACK(leap[Branch Path],leap[[2005]:[2024]]),(leap[Region]=B1)*(leap[Variable]=B2)), _xlpm.fval,_xlfn._xlws.FILTER(_xlpm.val,_xlfn.BYROW(_xlfn.DROP(_xlpm.val,,1),_xleta.SUM)>0), _xlpm.fuel,_xlfn.TEXTAFTER(_xlfn.TAKE(_xlpm.fval,,1),"\",3), _xlpm.mapping,VLOOKUP(_xlpm.fuel,Mapping!$B$3:$L$42,MATCH(_xlpm.country,AMS,0)+1,0), _xlpm.id,_xlfn.MAP(MATCH(_xlpm.mapping,_xlfn.TAKE(_xlpm.table,,1),0),_xlfn.LAMBDA(_xlpm.x,IFERROR(_xlpm.x,30))), _xlpm.fuel_val,_xlfn.TOCOL(_xlfn.DROP(_xlfn.CHOOSEROWS(_xlpm.table,_xlpm.id),,2),,1), _xlpm.r,2024-2005+1,_xlpm.l,B3, _xlpm.fuel_seq,_xlfn.TOCOL(IF(_xlfn.SEQUENCE(,_xlpm.r)<=_xlfn.CEILING.MATH(_xlfn.SEQUENCE(_xlpm.l)/_xlpm.l,1)-1+_xlpm.r,_xlpm.mapping,NA()),,1), _xlfn.HSTACK(_xlpm.fuel_seq,_xlpm.fuel_val))} -> Coal Subcritical | E8: 9750 | F8: {=ROUND(ABS(_xlfn.TAKE(_xlfn.ANCHORARRAY(B8),,-1)-_xlfn.TAKE(_xlfn.ANCHORARRAY(D8),,-1)),1)} -> 0 | H8: {=IFERROR(_xlfn._xlws.SORT(_xlfn._xlws.FILTER(_xlfn.HSTACK(_xlfn.ANCHORARRAY(A8),_xlfn.ANCHORARRAY(B8),_xlfn.ANCHORARRAY(D8)),_xlfn.ANCHORARRAY(F8)>0),2),"")} -> 2022 | I8: Coal Subcritical | J8: 42635.26 | K8: Coal Subcritical | L8: 42605.26 | O8: =J8-L8 -> 30
A9: 2005 | B9: Coal Supercritical | C9: 0 | D9: Coal Supercritical | E9: 0 | F9: 0 | H9: 2023 | I9: Coal Subcritical | J9: 49756.37 | K9: Coal Subcritical | L9: 46347.37 | O9: =J9-L9 -> 3409
A10: 2005 | B10: Diesel | C10: 3208.08 | D10: Diesel Oil | E10: 3208.08 | F10: 0 | H10: 2024 | I10: Coal Subcritical | J10: 54338.84 | K10: Coal Subcritical | L10: 50929.84 | O10: =J10-L10 -> 3409
A11: 2005 | B11: Gas Turbine | C11: 3099.35 | D11: Natural gas based Gas Turbine | E11: 3099.35 | F11: 0 | H11: 2023 | I11: Coal Supercritical | J11: 3942 | K11: Coal Supercritical | L11: 3409 | O11: =J11-L11 -> 533
A12: 2005 | B12: Gas Engine | C12: 3 | D12: Gas Engine | E12: 3 | F12: 0 | H12: 2024 | I12: Coal Supercritical | J12: 4301 | K12: Coal Supercritical | L12: 3409 | O12: =J12-L12 -> 892
A13: 2005 | B13: Gas Combined Cycle | C13: 6919.97 | D13: Combined Cycle Gas Turbine | E13: 6919.97 | F13: 0 | H13: 2018 | I13: Solar PV | J13: 52.61 | K13: Solar PV | L13: 60.19 | O13: =J13-L13 -> -7.58
A14: 2005 | B14: Large Hydro | C14: 3410.94 | D14: Large Hydro | E14: 3410.94 | F14: 0 | H14: 2022 | I14: Solar PV | J14: 272.22 | K14: Solar PV | L14: 283.14 | O14: =J14-L14 -> -10.92
A15: 2005 | B15: Small Hydro | C15: 0 | D15: Small Hydro | E15: 0 | F15: 0 | H15: 2023 | I15: Solar PV | J15: 589.05 | K15: Solar PV | L15: 599.97 | O15: =J15-L15 -> -10.92
A16: 2005 | B16: Geothermal Flash | C16: 850 | D16: Geothermal | E16: 850 | F16: 0 | H16: 2024 | I16: Solar PV | J16: 898.54 | K16: Solar PV | L16: 909.43 | O16: =J16-L16 -> -10.89
A17: 2005 | B17: Solar PV | C17: 0 | D17: Solar PV | E17: 0 | F17: 0 | H17: 2020 | I17: Wind Onshore | J17: 153.83 | K17: Wind Turbine | L17: 154.31 | O17: =J17-L17 -> -0.48
A18: 2005 | B18: Wind Onshore | C18: 0 | D18: Wind Turbine | E18: 0 | F18: 0 | O18: =J18-L18 -> 0
A19: 2005 | B19: Biomass Other | C19: 0 | D19: Biomass Other | E19: 0 | F19: 0 | O19: =J19-L19 -> 0
A20: 2005 | B20: Biogas | C20: 0 | D20: Biogas | E20: 0 | F20: 0 | O20: =J20-L20 -> 0
A21: 2005 | B21: Waste | C21: 0 | D21: Waste to Energy | E21: 0 | F21: 0
A22: 2006 | B22: Coal Subcritical | C22: 11170 | D22: Coal Subcritical | E22: 11170 | F22: 0
A23: 2006 | B23: Coal Supercritical | C23: 0 | D23: Coal Supercritical | E23: 0 | F23: 0
A24: 2006 | B24: Diesel | C24: 3165.05 | D24: Diesel Oil | E24: 3165.05 | F24: 0
A25: 2006 | B25: Gas Turbine | C25: 3102.95 | D25: Natural gas based Gas Turbine | E25: 3102.95 | F25: 0
A26: 2006 | B26: Gas Engine | C26: 21 | D26: Gas Engine | E26: 21 | F26: 0
A27: 2006 | B27: Gas Combined Cycle | C27: 7659.97 | D27: Combined Cycle Gas Turbine | E27: 7659.97 | F27: 0
A28: 2006 | B28: Large Hydro | C28: 3719.19 | D28: Large Hydro | E28: 3719.19 | F28: 0
A29: 2006 | B29: Small Hydro | C29: 0 | D29: Small Hydro | E29: 0 | F29: 0
A30: 2006 | B30: Geothermal Flash | C30: 850 | D30: Geothermal | E30: 850 | F30: 0
A31: 2006 | B31: Solar PV | C31: 0 | D31: Solar PV | E31: 0 | F31: 0
A32: 2006 | B32: Wind Onshore | C32: 0 | D32: Wind Turbine | E32: 0 | F32: 0
... A287: 2024 | B287: Waste | C287: 36.47 | D287: Waste to Energy | E287: 36.47 | F287: 0

Sheet Mapping
C2: {=TRANSPOSE(N4:N13)} -> Brunei | D2: Cambodia | E2: Indonesia | F2: Laos | G2: Malaysia | H2: Myanmar | I2: Philippines | J2: Singapore | K2: Thailand | L2: Vietnam
B3: {=_xlfn.LET(_xlpm.val,_xlfn.UNIQUE(_xlfn.TEXTAFTER(leap[Branch Path],"\",3)),_xlfn._xlws.SORT(_xlfn._xlws.FILTER(_xlpm.val,NOT(ISNUMBER(SEARCH("_",_xlpm.val))))))} -> Bioenergy with CCS | N3: Country
B4: Biogas | E4: Biogas | G4: Biogas | K4: Biogas | N4: Brunei
B5: Biomass Gasification | K5: Biomass Gasification | N5: Cambodia
B6: Biomass Other | D6: Biomass Other | E6: Biomass Other | F6: Biomass Other | G6: Biomass Other | H6: Biomass Other | I6: Biomass Other | K6: Biomass Other | L6: Biomass Other | N6: Indonesia
B7: CAES | N7: Laos
B8: Coal IGCC | C8: Coal based IGCC | N8: Malaysia
B9: Coal IGCC with CCS | N9: Myanmar
B10: Coal Subcritical | D10: Coal Subcritical | E10: Coal Subcritical | F10: Coal Subcritical | G10: Coal Subcritical | H10: Coal Subcritical | I10: Coal Subcritical | K10: Coal Subcritical | L10: Coal Subcritical | N10: Philippines
B11: Coal Supercritical | E11: Coal Supercritical | N11: Singapore
B12: Coal Supercritical CCS | N12: Thailand
B13: Coal Ultrasupercritical | G13: Coal Ultrasupercritical (USC) | N13: Vietnam
B14: Coal Ultrasupercritical CCS
B15: Diesel | C15: Diesel Oil | D15: Diesel Oil | E15: Diesel Oil | G15: Diesel Oil | H15: Diesel Oil | I15: Diesel Oil | K15: Diesel Oil | L15: Diesel Oil
B16: Direct Air Capture
B17: Fuel Oil | D17: Fuel Oil (Heavy Oil) | J17: Fuel Oil (Heavy Oil) | K17: Fuel Oil (Heavy Oil)
B18: Gas Combined Cycle | C18: Combined Cycle Gas Turbine | E18: Combined Cycle Gas Turbine | G18: Combined Cycle Gas Turbine | H18: Combined Cycle Gas Turbine (34%) | I18: Combined Cycle Gas Turbine | J18: Combined Cycle Gas Turbine | K18: Combined Cycle Gas Turbine | L18: Combined Cycle Gas Turbine
B19: Gas Combined Cycle with CCS
B20: Gas Engine | E20: Gas Engine | H20: Natural Gas Engine (29%)
B21: Gas Steam
B22: Gas Turbine | C22: Natural gas based Gas Turbine | E22: Natural gas based Gas Turbine | H22: Natural gas based Gas Turbine (37%) | J22: Natural gas based Gas Turbine
B23: Geothermal Flash | E23: Geothermal | I23: Geothermal | K23: Geothermal
B24: Geothermal ORC
B25: H2 Fuel Cell
B26: Large Hydro | D26: Large Hydro | E26: Large Hydro | F26: Large Hydro | G26: Large Hydro | H26: Large Hydro | I26: Large Hydro | K26: Large Hydro | L26: Large Hydro
B27: Lithium Ion Batteries
B28: Nuclear LWR
B29: Nuclear SFR
B30: Nuclear SMR
B31: Pumped Hydro | K31: Pumped Hydro Storage
B32: Small Hydro | E32: Small Hydro | H32: Small Hydro
B33: Solar CSP
B34: Solar Floating
B35: Solar PV | C35: Solar PV | D35: Solar PV | E35: Solar PV | F35: Solar PV | G35: Solar PV | H35: Solar PV | I35: Solar PV | J35: Solar PV | K35: Solar PV | L35: Solar PV
B36: Tidal
B37: Unmet Load
B38: VRB Flow Batteries
B39: Waste | E39: Waste to Energy | J39: Waste to Energy | K39: Waste to Energy
B40: Wave
B41: Wind Offshore
...

Sheet Vietnam_HP
A1: Technology | B1: Unit | C1: 2005 | D1: 2006 | E1: 2007 | F1: 2008 | G1: 2009 | H1: 2010 | I1: 2011 | J1: 2012 | K1: 2013 | L1: 2014 | M1: 2015 | N1: 2016 | O1: 2017 | P1: 2018 | Q1: 2019 | R1: 2020 | S1: 2021 | T1: 2022 | U1: 2023 | V1: 2024
A2: Coal Subcritical | B2: GWh | P2: 91654 | Q2: 120157 | R2: 123182 | S2: 118999 | T2: 104541 | U2: 130191 | V2: 156782
A3: Coal Supercritical | B3: GWh
A4: Coal Ultrasupercritical (USC) | B4: GWh
A5: Coal with CCS | B5: GWh
A6: Coal based IGCC | B6: GWh
A7: Coal based IGCC with CCS | B7: GWh
A8: Oil based Gas Turbine | B8: GWh
A9: Diesel Oil | B9: GWh | P9: 751 | Q9: 2213 | R9: 15 | S9: 4 | T9: 22 | U9: 29 | V9: 25
A10: Fuel Oil (Heavy Oil) | B10: GWh | R10: 1041 | S10: 2 | T10: 56 | U10: 1248 | V10: 175
A11: Other IGCC | B11: GWh
A12: Natural gas based Gas Turbine | B12: GWh
A13: Natural gas based IGCC | B13: GWh
A14: Combined Cycle Gas Turbine | B14: GWh | P14: 40562 | Q14: 42402 | R14: 34800 | S14: 26311 | T14: 29410 | U14: 26372 | V14: 21829
A15: Large Hydro | B15: GWh | P15: 83081 | Q15: 66117 | R15: 72832 | S15: 78393 | T15: 95848 | U15: 80595 | V15: 88723
A16: Small Hydro | B16: GWh
A17: Pumped Hydro Storage | B17: GWh
A18: Nuclear | B18: GWh
A19: Geothermal | B19: GWh
A20: Solar PV | B20: GWh | P20: 22 | Q20: 4818 | R20: 10281 | S20: 27762 | T20: 28397 | U20: 27222 | V20: 27777
A21: Solar Thermal | B21: GWh
A22: Ocean | B22: GWh
A23: Wind Turbine | B23: GWh | P23: 487 | Q23: 724 | R23: 982 | S23: 3349 | T23: 9090 | U23: 11583 | V23: 12747
A24: Biomass Other | B24: GWh | P24: 488 | Q24: 350 | R24: 340 | S24: 321 | T24: 378 | U24: 867 | V24: 1032
A25: Biomass Gasification | B25: GWh
A26: Biomass Gasification with CCS | B26: GWh
A27: Biodiesel | B27: GWh
A28: Fuel Cell (Hydrogen) | B28: GWh
A29: Biogas | B29: GWh
A30: Battery | B30: GWh
A31: Others | B31: GWh
A32: Gas Engine | B32: GWh
A33: Waste to Energy | B33: GWh
A34: Total | B34: GWh | U34: 278107 | V34: 309090

Sheet Thailand_HP
A1: Technology | B1: Unit | C1: 2005 | D1: 2006 | E1: 2007 | F1: 2008 | G1: 2009 | H1: 2010 | I1: 2011 | J1: 2012 | K1: 2013 | L1: 2014 | M1: 2015 | N1: 2016 | O1: 2017 | P1: 2018 | Q1: 2019 | R1: 2020 | S1: 2021 | T1: 2022 | U1: 2023 | V1: 2024
A2: Coal Subcritical | B2: GWh | C2: 32034 | D2: 35051 | E2: 36615.8 | F2: 37480.6 | G2: 37825 | H2: 38854.2 | I2: 40047.8 | J2: 40081 | K2: 36374 | L2: 35753 | M2: 34582.1 | N2: 37038 | O2: 35782.1 | P2: 35796.424 | Q2: 35825.22 | R2: 45902.293 | S2: 45531.515 | T2: 45519.511 | U2: 30430 | V2: 33280
A3: Coal Supercritical | B3: GWh | C3: 0 | D3: 0 | E3: 0 | F3: 0 | G3: 0 | H3: 0 | I3: 0 | J3: 0 | K3: 0 | L3: 0 | M3: 0 | N3: 0 | O3: 0 | P3: 0 | Q3: 0 | R3: 0
A4: Coal Ultrasupercritical (USC) | B4: GWh | C4: 0 | D4: 0 | E4: 0 | F4: 0 | G4: 0 | H4: 0 | I4: 0 | J4: 0 | K4: 0 | L4: 0 | M4: 0 | N4: 0 | O4: 0 | P4: 0 | Q4: 0 | R4: 0
A5: Coal with CCS | B5: GWh
A6: Coal based IGCC | B6: GWh
A7: Coal based IGCC with CCS | B7: GWh
A8: Oil based Gas Turbine | B8: GWh | C8: 0 | D8: 0 | E8: 0 | F8: 0 | G8: 0 | H8: 0 | I8: 0 | J8: 0 | K8: 0 | L8: 0 | M8: 0 | N8: 0 | O8: 0 | P8: 0 | Q8: 0 | R8: 486.32121 | S8: 17.664005 | T8: 0
A9: Diesel Oil | B9: GWh | C9: 5949.3 | D9: 5646.3 | E9: 5526.5 | F9: 5216.2 | G9: 3153 | H9: 2573.1 | I9: 2050 | J9: 2222 | K9: 1584.6 | L9: 1399 | M9: 914.9 | N9: 630.8 | O9: 334.2 | P9: 111.772 | Q9: 137.224 | R9: 226.32416 | S9: 1750.9199 | T9: 9297.9069
A10: Fuel Oil (Heavy Oil) | B10: GWh | R10: 97.966457 | S10: 953.39445 | T10: 1263.3032
A11: Other IGCC | B11: GWh
A12: Natural gas based Gas Turbine | B12: GWh
A13: Natural gas based IGCC | B13: GWh
A14: Combined Cycle Gas Turbine | B14: GWh | C14: 85703 | D14: 87071 | E14: 90167.2 | F14: 94549 | G14: 82569.3 | H14: 94224 | I14: 102301 | J14: 114628 | K14: 118871.2 | L14: 124675 | M14: 128525 | N14: 124597 | O14: 120263.6 | P14: 116265.18 | Q14: 121840.62 | R14: 112793.07 | S14: 110171.31 | T14: 104931.22 | U14: 129400 | V14: 136370
A15: Gas Engine | B15: GWh
A16: Large Hydro | B16: GWh | C16: 5798.7 | D16: 8125 | E16: 8114 | F16: 7113 | G16: 7148 | H16: 5537 | I16: 8164 | J16: 8641.3 | K16: 5611 | L16: 4362.3 | M16: 3867.7 | N16: 3651 | O16: 4832.8 | P16: 7597.013 | Q16: 6309.958 | R16: 20792.732 | S16: 24084.506 | T16: 27515.972 | U16: 6590 | V16: 6410
A17: Small Hydro | B17: GWh
A18: Pumped Hydro Storage | B18: GWh | C18: 0 | D18: 0 | E18: 0 | F18: 0 | G18: 0 | H18: 0 | I18: 0 | J18: 0 | K18: 0 | L18: 0 | M18: 0 | N18: 0 | O18: 0 | P18: 0 | Q18: 0 | R18: 457.12838 | S18: 389.4861 | T18: 333.9196
A19: Nuclear | B19: GWh
A20: Geothermal | B20: GWh | C20: 1 | D20: 1 | E20: 1 | F20: 1 | G20: 2 | H20: 3 | I20: 1.2 | J20: 1 | K20: 1.3 | L20: 1 | M20: 1.3 | N20: 1 | O20: 1.5 | P20: 1.5 | Q20: 1.5 | R20: 1.01155 | S20: 1.35933 | T20: 1.388838
A21: Solar PV | B21: GWh | C21: 0 | D21: 0 | E21: 0 | F21: 0 | G21: 9 | H21: 23 | I21: 83 | J21: 447 | K21: 931.4 | L21: 2031 | M21: 2318.5 | N21: 3553.5 | O21: 4542.5 | P21: 4542.5 | Q21: 4542.5 | R21: 4773.4595 | S21: 4780.4798 | T21: 4792.989 | U21: 5420 | V21: 6170
A22: Solar Thermal | B22: GWh
A23: Ocean | B23: GWh
A24: Wind Turbine | B24: GWh | C24: 0 | D24: 0 | E24: 0 | F24: 0 | G24: 1 | H24: 2 | I24: 5 | J24: 17 | K24: 351.3 | L24: 406 | M24: 359.6 | N24: 349.7 | O24: 1109.9 | P24: 1109.9 | Q24: 1109.9 | R24: 3118.3411 | S24: 3409.7693 | T24: 2957.9234 | U24: 3610 | V24: 3670
A25: Biomass Other | B25: GWh | C25: 0 | D25: 0 | E25: 0 | F25: 0 | G25: 0 | H25: 0 | I25: 3123 | J25: 4999.7 | K25: 4949.8 | L25: 4918 | M25: 12379.9 | N25: 15674.4 | O25: 15032.8 | P25: 15032.8 | Q25: 15032.8 | R25: 0 | S25: 0 | T25: 0
A26: Biomass Gasification | B26: GWh | C26: 0 | D26: 0 | E26: 0 | F26: 0 | G26: 0 | H26: 0 | I26: 0 | J26: 0 | K26: 0 | L26: 0 | M26: 0 | N26: 0 | O26: 0 | P26: 0 | Q26: 0 | R26: 9564.3092 | S26: 10223.776 | T26: 10932.555 | U26: 14150 | V26: 13400
A27: Biomass Gasification with CCS | B27: GWh
A28: Biodiesel | B28: GWh
A29: Biogas | B29: GWh | C29: 0 | D29: 0 | E29: 0 | F29: 0 | G29: 0 | H29: 0 | I29: 0 | J29: 231 | K29: 918.5 | L29: 921.8 | M29: 1400.9 | N29: 2144.6 | O29: 3610.8 | P29: 3610.8 | Q29: 3610.8 | R29: 829.06219 | S29: 828.7184 | T29: 864.81539
A30: Waste to Energy | B30: GWh | C30: 0 | D30: 0 | E30: 0 | F30: 0 | G30: 0 | H30: 0 | I30: 0 | J30: 0 | K30: 0 | L30: 0 | M30: 0 | N30: 0 | O30: 0 | P30: 0 | Q30: 0 | R30: 2164.8038 | S30: 2356.6975 | T30: 2223.2466
A31: Fuel Cell (Hydrogen) | B31: GWh
A32: Battery | B32: GWh
A33: Others | B33: GWh | R33: 2125.0128 | S33: 2172.495 | T33: 2560.4257 | U33: 33550 | V33: 37080
A34: Total | B34: GWh | C34: 129486 | D34: 135894.3 | E34: 140424.5 | F34: 144359.8 | G34: 130707.3 | H34: 141216.3 | I34: 155775 | J34: 171268 | K34: 169593.1 | L34: 174467.1 | M34: 184349.9 | N34: 187640 | O34: 185510.2 | P34: 184067.88 | Q34: 188410.52 | R34: 203331.84 | S34: 206672.09 | T34: 213195.18 | U34: 223150 | V34: 236380

Sheet Singapore_HP
A1: Technology | B1: Unit | C1: 2005 | D1: 2006 | E1: 2007 | F1: 2008 | G1: 2009 | H1: 2010 | I1: 2011 | J1: 2012 | K1: 2013 | L1: 2014 | M1: 2015 | N1: 2016 | O1: 2017 | P1: 2018 | Q1: 2019 | R1: 2020 | S1: 2021 | T1: 2022 | U1: 2023 | V1: 2024
A2: Coal Subcritical | B2: GWh | C2: 0 | D2: 0 | E2: 0 | F2: 0 | G2: 0 | H2: 0 | I2: 0 | J2: 0 | K2: 0 | L2: 0 | M2: 0 | N2: 0 | O2: 0 | P2: 0 | Q2: 0 | R2: 0 | S2: 0 | T2: 0
A3: Coal Supercritical | B3: GWh | C3: 0 | D3: 0 | E3: 0 | F3: 0 | G3: 0 | H3: 0 | I3: 0 | J3: 0 | K3: 0 | L3: 0 | M3: 0 | N3: 0 | O3: 0 | P3: 0 | Q3: 0 | R3: 0 | S3: 0 | T3: 0
A4: Coal Ultrasupercritical (USC) | B4: GWh | C4: 0 | D4: 0 | E4: 0 | F4: 0 | G4: 0 | H4: 0 | I4: 0 | J4: 0 | K4: 0 | L4: 0 | M4: 0 | N4: 0 | O4: 0 | P4: 0 | Q4: 0 | R4: 0 | S4: 0 | T4: 0
A5: Coal with CCS | B5: GWh
A6: Coal based IGCC | B6: GWh
A7: Coal based IGCC with CCS | B7: GWh
A8: Oil based Gas Turbine | B8: GWh
A9: Diesel Oil | B9: GWh | C9: 0 | D9: 0 | E9: 0 | F9: 0 | G9: 0 | H9: 0 | I9: 0 | J9: 0 | K9: 0 | L9: 0 | M9: 0 | N9: 0 | O9: 0 | P9: 0 | Q9: 0 | R9: 0 | S9: 0 | T9: 0
A10: Fuel Oil (Heavy Oil) | B10: GWh | C10: 8827 | D10: 7817 | E10: 7774 | F10: 7167 | G10: 7064 | H10: 9164 | I10: 8924 | J10: 6102 | K10: 2249 | L10: 345 | M10: 332 | N10: 361 | O10: 366 | Q10: 217 | R10: 211 | S10: 440 | T10: 458.92
A11: Other IGCC | B11: GWh
A12: Natural gas based Gas Turbine | B12: GWh | C12: 1692 | D12: 1936 | E12: 1910 | F12: 2017 | G12: 2361 | H12: 1986 | I12: 1571 | J12: 890 | K12: 825 | L12: 841 | M12: 818 | N12: 839 | O12: 837 | P12: 876.17315 | Q12: 871.37697 | R12: 850.90567 | S12: 881.78096 | T12: 919.69755
A13: Natural gas based IGCC | B13: GWh
A14: Combined Cycle Gas Turbine | B14: GWh | C14: 26738 | D14: 28780 | E14: 30463 | F14: 31444 | G14: 31330 | H14: 33036 | I14: 34308 | J14: 38677 | K14: 43201 | L14: 46191 | M14: 47070 | N14: 48271 | O14: 48881 | P14: 51168.722 | Q14: 50888.623 | R14: 49693.094 | S14: 51496.219 | T14: 53710.556
A15: Large Hydro | B15: GWh | C15: 0 | D15: 0 | E15: 0 | F15: 0 | G15: 0 | H15: 0 | I15: 0 | J15: 0 | K15: 0 | L15: 0 | M15: 0 | N15: 0 | O15: 0 | P15: 0 | Q15: 0 | R15: 0 | S15: 0 | T15: 0
A16: Small Hydro | B16: GWh
A17: Pumped Hydro Storage | B17: GWh
A18: Nuclear | B18: GWh
A19: Geothermal | B19: GWh | C19: 0 | D19: 0 | E19: 0 | F19: 0 | G19: 0 | H19: 0 | I19: 0 | J19: 0 | K19: 0 | L19: 0 | M19: 0 | N19: 0 | O19: 0 | P19: 0 | Q19: 0 | R19: 0 | S19: 0 | T19: 0
A20: Solar PV | B20: GWh | C20: 0 | D20: 0 | E20: 0 | F20: 1 | G20: 3 | H20: 5 | I20: 8 | J20: 13 | K20: 17 | L20: 38 | M20: 69 | N20: 146 | O20: 169 | P20: 268.61035 | Q20: 410 | R20: 499 | S20: 761 | T20: 793.723
A21: Solar Thermal | B21: GWh
A22: Ocean | B22: GWh
A23: Wind Turbine | B23: GWh | C23: 0 | D23: 0 | E23: 0 | F23: 0 | G23: 0 | H23: 0 | I23: 0 | J23: 0 | K23: 0 | L23: 0 | M23: 0 | N23: 0 | O23: 0 | P23: 0 | Q23: 0 | R23: 0 | S23: 0 | T23: 0
A24: Biomass Other | B24: GWh | C24: 0 | D24: 0 | E24: 0 | F24: 0 | G24: 0 | H24: 0 | I24: 0 | J24: 0 | K24: 0 | L24: 0 | M24: 0 | N24: 0 | O24: 0 | P24: 0 | Q24: 0 | R24: 0 | S24: 0 | T24: 0
A25: Biomass Gasification | B25: GWh
A26: Biomass Gasification with CCS | B26: GWh
A27: Biodiesel | B27: GWh
A28: Fuel Cell (Hydrogen) | B28: GWh
A29: Biogas | B29: GWh | C29: 0 | D29: 0 | E29: 0 | F29: 0 | G29: 0 | H29: 0 | I29: 0 | J29: 0 | K29: 0 | L29: 0 | M29: 0 | N29: 0 | O29: 0 | P29: 0 | Q29: 0 | R29: 0 | S29: 0 | T29: 0
A30: Battery | B30: GWh
A31: Others | B31: GWh
A32: Gas Engine | B32: GWh
A33: Waste to Energy | B33: GWh | C33: 955.3 | D33: 947.5 | E33: 987.2 | F33: 1040.8 | G33: 1042 | H33: 1174.5 | I33: 1188 | J33: 1254.3 | K33: 1671.3 | L33: 1894.9 | M33: 1982.1 | N33: 1969.1 | O33: 1972.2 | P33: 563.78043 | Q33: 1433 | R33: 1054 | S33: 1220 | T33: 1272.46
A34: Total | B34: GWh | C34: 38212.3 | D34: 39480.5 | E34: 41134.2 | F34: 41669.8 | G34: 41800 | H34: 45365.5 | I34: 45999 | J34: 46936.3 | K34: 47963.3 | L34: 49309.9 | M34: 50271.1 | N34: 51586.1 | O34: 52225.2 | P34: 52877.285 | Q34: 53820 | R34: 52308 | S34: 54799 | T34: 57155.357

Sheet Philippines_HP
A1: Technology | B1: Unit | C1: 2005 | D1: 2006 | E1: 2007 | F1: 2008 | G1: 2009 | H1: 2010 | I1: 2011 | J1: 2012 | K1: 2013 | L1: 2014 | M1: 2015 | N1: 2016 | O1: 2017 | P1: 2018 | Q1: 2019 | R1: 2020 | S1: 2021 | T1: 2022 | U1: 2023 | V1: 2024
A2: Coal Subcritical | B2: GWh | C2: 15257.2 | D2: 15294.1 | E2: 16837.1 | F2: 15748.8 | G2: 16476.1 | H2: 23301.1 | I2: 25342.2 | J2: 28264.9 | K2: 32081 | L2: 33053.5 | M2: 36685.7 | N2: 43303.2 | O2: 46847.3 | P2: 51932.187 | Q2: 57890.429 | R2: 58176.002 | S2: 62052.246 | T2: 66429.544 | U2: 73753.848 | V2: 79359.333
A3: Coal Supercritical | B3: GWh
A4: Coal Ultrasupercritical (USC) | B4: GWh
A5: Coal with CCS | B5: GWh
A6: Coal based IGCC | B6: GWh
A7: Coal based IGCC with CCS | B7: GWh
A8: Oil based Gas Turbine | B8: GWh
A9: Diesel Oil | B9: GWh | C9: 6141.4 | D9: 4664.8 | E9: 5148 | F9: 4868.3 | G9: 5380.7 | H9: 7101 | I9: 3397.6 | J9: 4254 | K9: 4490.6 | L9: 5707.7 | M9: 5886.4 | N9: 5661.4 | O9: 3787.1 | P9: 3172.8171 | Q9: 3752.3018 | R9: 2473.8877 | S9: 1616.3781 | T9: 2518.5002 | U9: 1303.644 | V9: 1341.6626
A10: Fuel Oil (Heavy Oil) | B10: GWh
A11: Other IGCC | B11: GWh
A12: Natural gas based Gas Turbine | B12: GWh
A13: Natural gas based IGCC | B13: GWh
A14: Combined Cycle Gas Turbine | B14: GWh | C14: 16860.9 | D14: 16366 | E14: 18789.4 | F14: 19575.9 | G14: 19886.8 | H14: 19517.9 | I14: 20591.3 | J14: 19641.5 | K14: 18791.3 | L14: 18690.1 | M14: 18877.9 | N14: 19853.8 | O14: 20547.2 | P14: 21333.789 | Q14: 22354.378 | R14: 19496.927 | S14: 18675.444 | T14: 17884.12 | U14: 16668.066 | V14: 18046.729
A15: Large Hydro | B15: GWh | C15: 8386.773 | D15: 9939.413 | E15: 8563.433 | F15: 9842.534 | G15: 9787.567 | H15: 7803.405 | I15: 9697.532 | J15: 10252.134 | K15: 10019.308 | L15: 9137.273 | M15: 8665.078 | N15: 8110.915 | O15: 9610.799 | P15: 9383.7582 | Q15: 8025.4917 | R15: 7192.0188 | S15: 9185.3235 | T15: 10084.592 | U15: 10287.161 | V15: 10908.597
A16: Small Hydro | B16: GWh
A17: Pumped Hydro Storage | B17: GWh
A18: Nuclear | B18: GWh
A19: Geothermal | B19: GWh | C19: 9902 | D19: 10465 | E19: 10215 | F19: 10723 | G19: 10324 | H19: 9929 | I19: 9942 | J19: 10250 | K19: 9605 | L19: 10308 | M19: 11044 | N19: 11070 | O19: 10270 | P19: 10435.305 | Q19: 10690.804 | R19: 10756.815 | S19: 10681.422 | T19: 10424.518 | U19: 10730.183 | V19: 10789.22
A20: Solar PV | B20: GWh | C20: 1.5 | D20: 1.4 | E20: 1.3 | F20: 1.3 | G20: 1.3 | H20: 1.3 | I20: 1.2 | J20: 1.3 | K20: 1.4 | L20: 16.5 | M20: 138.5 | N20: 1097 | O20: 1201.2 | P20: 1249.1164 | Q20: 1246.0817 | R20: 1372.6045 | S20: 1469.5499 | T20: 1822.3958 | U20: 2544.0051 | V20: 3810.6931
A21: Solar Thermal | B21: GWh
A22: Ocean | B22: GWh
A23: Wind Turbine | B23: GWh | C23: 17.5 | D23: 53.2 | E23: 57.8 | F23: 61.4 | G23: 64.4 | H23: 61.7 | I23: 88.2 | J23: 75.3 | K23: 65.7 | L23: 152.1 | M23: 748.4 | N23: 975.2 | O23: 1093.6 | P23: 1152.923 | Q23: 1041.6599 | R23: 1026.4498 | S23: 1269.6616 | T23: 1029.8689 | U23: 1308.1384 | V23: 1238.6711
A24: Biomass Other | B24: GWh | C24: 0 | D24: 0 | E24: 0 | F24: 0 | G24: 13.7 | H24: 27.3 | I24: 115.3 | J24: 182.8 | K24: 212 | L24: 195.7 | M24: 367.5 | N24: 725.9 | O24: 1013.1 | P24: 1104.8228 | Q24: 1040.3426 | R24: 1261.016 | S24: 1164.6887 | T24: 1322.1298 | U24: 1408.8628 | V24: 1445.9211
A25: Biomass Gasification | B25: GWh
A26: Biomass Gasification with CCS | B26: GWh
A27: Biodiesel | B27: GWh
A28: Fuel Cell (Hydrogen) | B28: GWh
A29: Biogas | B29: GWh
A30: Battery | B30: GWh
A31: Others | B31: GWh
A32: Total | B32: GWh | C32: 56567.273 | D32: 56783.913 | E32: 59612.033 | F32: 60821.234 | G32: 61934.567 | H32: 67742.705 | I32: 69175.332 | J32: 72921.934 | K32: 75266.308 | L32: 77260.873 | M32: 82413.478 | N32: 90797.415 | O32: 94370.299 | P32: 99764.718 | Q32: 106041.49 | R32: 101755.72 | S32: 106114.71 | T32: 111515.67 | U32: 118003.91 | V32: 126940.83

Sheet Myanmar_HP
A1: Technology | B1: Unit | C1: 2005 | D1: 2006 | E1: 2007 | F1: 2008 | G1: 2009 | H1: 2010 | I1: 2011 | J1: 2012 | K1: 2013 | L1: 2014 | M1: 2015 | N1: 2016 | O1: 2017 | P1: 2018 | Q1: 2019 | R1: 2020 | S1: 2021 | T1: 2022 | U1: 2023 | V1: 2024
A2: Coal Subcritical | B2: GWh | C2: 232.66 | D2: 382.21 | E2: 401.82 | F2: 198.39 | G2: 228.95 | H2: 365.91 | I2: 292.13 | J2: 241.71 | K2: 125.6 | L2: 66.1 | M2: 0 | N2: 9.3 | O2: 438.67 | P2: 561.69 | Q2: 692.96 | R2: 554.115 | S2: 661.89 | T2: 705.339 | U2: 759.458 | V2: 632.788
A3: Coal Supercritical | B3: GWh | C3: 0 | D3: 0 | E3: 0 | F3: 0 | G3: 0 | H3: 0 | I3: 0 | J3: 0 | K3: 0 | L3: 0 | M3: 0 | N3: 0 | O3: 0 | P3: 0 | Q3: 0 | R3: 0 | S3: 0 | T3: 0 | U3: 0 | V3: 0
A4: Coal Ultrasupercritical (USC) | B4: GWh | C4: 0 | D4: 0 | E4: 0 | F4: 0 | G4: 0 | H4: 0 | I4: 0 | J4: 0 | K4: 0 | L4: 0 | M4: 0 | N4: 0 | O4: 0 | P4: 0 | Q4: 0 | R4: 0 | S4: 0 | T4: 0 | U4: 0 | V4: 0
A5: Coal with CCS | B5: GWh
A6: Coal based IGCC | B6: GWh
A7: Coal based IGCC with CCS | B7: GWh
A8: Oil based Gas Turbine | B8: GWh
A9: Diesel Oil | B9: GWh | C9: 32.24 | D9: 27.14 | E9: 31.73 | F9: 37.12 | G9: 27.83 | H9: 31.17 | I9: 36.65 | J9: 47.51 | K9: 57.61 | L9: 62.65 | M9: 53.57 | N9: 59.84 | O9: 67.54 | P9: 82.7 | Q9: 136.11 | R9: 176.39 | S9: 114.3 | T9: 100.984 | U9: 98.065 | V9: 95.153
A10: Fuel Oil (Heavy Oil) | B10: GWh
A11: Other IGCC | B11: GWh
A12: Natural gas based Gas Turbine (37%) | B12: GWh | C12: 1010.74 | D12: 874.7 | E12: 827.48 | F12: 814.53 | G12: 510.72 | H12: 725.01 | I12: 922.06 | J12: 1029.12 | K12: 1158.78 | L12: 1883.49 | M12: 2370.07 | N12: 2943.77 | O12: 3053.49 | P12: 3439.0523 | Q12: 4541.1868 | R12: 5501.8976 | S12: 4615.7345 | T12: 4696.4929 | U12: 3857.7073 | V12: 3337.9543
A13: Natural gas based IGCC | B13: GWh
A14: Combined Cycle Gas Turbine (56%) | B14: GWh | C14: 1720.99 | D14: 1489.35 | E14: 1408.96 | F14: 1386.91 | G14: 869.61 | H14: 1234.47 | I14: 1570 | J14: 1752.29 | K14: 1753.83 | L14: 2850.69 | M14: 3587.13 | N14: 4455.43 | O14: 4621.5 | P14: 5205.0455 | Q14: 6873.1389 | R14: 8327.1858 | S14: 6985.9676 | T14: 6771.69 | U14: 5838.6922 | V14: 5052.0389
A15: Natural Gas Engine (7%) | B15: GWh | C15: 0 | D15: 0 | E15: 0 | F15: 0 | G15: 0 | H15: 0 | I15: 0 | J15: 0 | K15: 219.23 | L15: 356.34 | M15: 448.39 | N15: 556.93 | O15: 577.69 | P15: 650.63215 | Q15: 859.14429 | R15: 1040.9006 | S15: 873.24791 | T15: 0 | U15: 729.83652 | V15: 631.50486
A16: Large Hydro | B16: GWh | C16: 2986.31 | D16: 3308.76 | E16: 3589.87 | F16: 4031.34 | G16: 5212.17 | H16: 6148.15 | I16: 7496.8 | J16: 7697.84 | K16: 8713.03 | L16: 8790.99 | M16: 9359.79 | N16: 9714.72 | O16: 11161.26 | P16: 12359.13 | Q16: 10032.27 | R16: 8025.071 | S16: 9919.25 | T16: 9021.003 | U16: 9281.867 | V16: 8738.688
A17: Small Hydro | B17: GWh | C17: 0 | D17: 0 | E17: 0 | F17: 0 | G17: 0 | H17: 0 | I17: 0 | J17: 0 | K17: 0 | L17: 0 | M17: 0 | N17: 0 | O17: 0 | P17: 0 | Q17: 0 | R17: 0 | T17: 48.926
A18: Pumped Hydro Storage | B18: GWh
A19: Nuclear | B19: GWh
A20: Geothermal | B20: GWh | C20: 0 | D20: 0 | E20: 0 | F20: 0 | G20: 0 | H20: 0 | I20: 0 | J20: 0 | K20: 0 | L20: 0 | M20: 0 | N20: 0 | O20: 0 | P20: 0 | Q20: 0 | R20: 0 | S20: 0 | T20: 0 | U20: 0 | V20: 0
A21: Solar PV | B21: GWh | C21: 0 | D21: 0 | E21: 0 | F21: 0 | G21: 0 | H21: 0 | I21: 4.32 | J21: 4.32 | K21: 0 | L21: 0 | M21: 0 | N21: 0 | O21: 0 | P21: 11.8 | Q21: 67.92 | R21: 105.403 | S21: 111.858 | T21: 194.409 | U21: 387.667 | V21: 494.39425
A22: Solar Thermal | B22: GWh
A23: Ocean | B23: GWh
A24: Wind Turbine | B24: GWh | C24: 0 | D24: 0 | E24: 0 | F24: 0 | G24: 0 | H24: 0.02 | I24: 0 | J24: 0 | K24: 0 | L24: 0 | M24: 0 | N24: 0 | O24: 0 | P24: 0 | Q24: 0 | R24: 0 | S24: 0 | T24: 0 | U24: 0 | V24: 0
A25: Biomass Other | B25: GWh | C25: 0 | D25: 0 | E25: 0 | F25: 0 | G25: 0 | H25: 0 | I25: 0 | J25: 0 | K25: 0 | L25: 0 | M25: 0 | N25: 0 | O25: 0 | P25: 0 | Q25: 0 | R25: 0 | S25: 0 | T25: 0 | U25: 0 | V25: 0
A26: Biomass Gasification | B26: GWh
A27: Biomass Gasification with CCS | B27: GWh
A28: Biodiesel | B28: GWh
A29: Fuel Cell (Hydrogen) | B29: GWh
A30: Biogas | B30: GWh | C30: 0 | D30: 0 | E30: 0 | F30: 0 | G30: 0 | H30: 0 | I30: 0 | J30: 0 | K30: 0 | L30: 0 | M30: 0 | N30: 0 | O30: 0 | P30: 0 | Q30: 0 | R30: 0 | S30: 0 | T30: 0 | U30: 0 | V30: 0
A31: Battery | B31: GWh
A32: Others | B32: GWh
A33: Total | B33: GWh | C33: 5982.94 | D33: 6082.16 | E33: 6259.86 | F33: 6468.29 | G33: 6849.28 | H33: 8504.73 | I33: 10321.96 | J33: 10772.79 | K33: 12028.08 | L33: 14010.26 | M33: 15818.95 | N33: 17739.99 | O33: 19920.15 | P33: 22310.05 | Q33: 23202.73 | R33: 23730.963 | S33: 23282.248 | T33: 21538.844 | U33: 20953.293 | V33: 18982.521

Sheet Malaysia_HP
A1: Technology | B1: Unit | C1: 2005 | D1: 2006 | E1: 2007 | F1: 2008 | G1: 2009 | H1: 2010 | I1: 2011 | J1: 2012 | K1: 2013 | L1: 2014 | M1: 2015 | N1: 2016 | O1: 2017 | P1: 2018 | Q1: 2019 | R1: 2020 | S1: 2021 | T1: 2022 | U1: 2023 | V1: 2024
A2: Coal Subcritical | B2: GWh | C2: 24228 | D2: 26527 | E2: 32932 | F2: 36585 | G2: 44329 | H2: 47595 | I2: 48932 | J2: 52584 | K2: 50747 | L2: 50536 | M2: 52004 | N2: 51853 | O2: 51643 | P2: 61828.8 | Q2: 61128.8 | R2: 71100.288 | S2: 67867.326 | T2: 65777.6 | U2: 68496 | V2: 71604
A3: Coal Supercritical | B3: GWh | C3: 0 | D3: 0 | E3: 0 | F3: 0 | G3: 0 | H3: 0 | I3: 0 | J3: 0 | K3: 0 | L3: 0 | M3: 0 | N3: 0 | O3: 0 | P3: 0 | Q3: 0 | R3: 0 | S3: 0 | T3: 0 | U3: 0 | V3: 0
A4: Coal Ultrasupercritical (USC) | B4: GWh | C4: 0 | D4: 0 | E4: 0 | F4: 0 | G4: 0 | H4: 0 | I4: 0 | J4: 0 | K4: 0 | L4: 0 | M4: 4655 | N4: 11304 | O4: 14050 | P4: 15457.2 | Q4: 15282.2 | R4: 17775.072 | S4: 16966.831 | T4: 16444.4 | U4: 17124 | V4: 17901
A5: Coal with CCS | B5: GWh
A6: Coal based IGCC | B6: GWh
A7: Coal based IGCC with CCS | B7: GWh
A8: Oil based Gas Turbine | B8: GWh
A9: Diesel Oil | B9: GWh | C9: 1396 | D9: 1908 | E9: 1768 | F9: 1649 | G9: 1726 | H9: 1659 | I9: 9403 | J9: 6014 | K9: 5339 | L9: 3490 | M9: 1739 | N9: 1184 | O9: 1695 | P9: 929 | Q9: 1010 | R9: 845.96028 | S9: 975.21511 | T9: 2803 | U9: 2752 | V9: 1238
A10: Fuel Oil (Heavy Oil) | B10: GWh | C10: 0 | D10: 0 | E10: 0 | F10: 0 | G10: 0 | H10: 0 | I10: 0 | J10: 0 | K10: 0 | L10: 0 | M10: 0 | N10: 0 | O10: 0 | P10: 0 | Q10: 0 | R10: 0 | S10: 0 | T10: 0 | U10: 0 | V10: 0
A11: Other IGCC | B11: GWh
A12: Natural gas based Gas Turbine | B12: GWh | C12: 0 | D12: 0 | E12: 0 | F12: 0 | G12: 0 | H12: 0 | I12: 0 | J12: 0 | K12: 0 | L12: 0 | M12: 0 | N12: 0 | O12: 0 | P12: 0 | Q12: 0 | R12: 0 | S12: 0 | T12: 0 | U12: 0 | V12: 0
A13: Natural gas based IGCC | B13: GWh
A14: Combined Cycle Gas Turbine | B14: GWh | C14: 61396 | D14: 64768 | E14: 65568 | F14: 67779 | G14: 63370 | H14: 61342 | I14: 55732 | J14: 62699 | K14: 67761 | L14: 73836 | M14: 69962 | N14: 66833 | O14: 62131 | P14: 64053 | Q14: 72280 | R14: 53690.939 | S14: 58418.957 | T14: 70289 | U14: 74826 | V14: 75168
A15: Large Hydro | B15: GWh | C15: 6007 | D15: 6323 | E15: 5957 | F15: 7807 | G15: 6890 | H15: 6361 | I15: 8056 | J15: 9056 | K15: 10586 | L15: 13388 | M15: 13924 | N15: 20024 | O15: 26846 | P15: 26325 | Q15: 26196 | R15: 27299.327 | S15: 31105.086 | T15: 31934 | U15: 32014 | V15: 33697
A16: Small Hydro | B16: GWh
A17: Pumped Hydro Storage | B17: GWh
A18: Nuclear | B18: GWh
A19: Geothermal | B19: GWh | C19: 0 | D19: 0 | E19: 0 | F19: 0 | G19: 0 | H19: 0 | I19: 0 | J19: 0 | K19: 0 | L19: 0 | M19: 0 | N19: 0 | O19: 0 | P19: 0 | Q19: 0 | R19: 0 | S19: 0 | T19: 0 | U19: 0 | V19: 0
A20: Solar PV | B20: GWh | C20: 0 | D20: 0 | E20: 0 | F20: 0 | G20: 0 | H20: 0 | I20: 0 | J20: 47.2 | K20: 140.5 | L20: 226.9 | M20: 273.2 | N20: 310.5 | O20: 330.3 | P20: 632 | Q20: 1459 | R20: 2058.8548 | S20: 2101.5238 | T20: 3412 | U20: 4403 | V20: 6369
A21: Solar Thermal | B21: GWh
A22: Ocean | B22: GWh
A23: Wind Turbine | B23: GWh | C23: 0 | D23: 0 | E23: 0 | F23: 0 | G23: 0 | H23: 0 | I23: 0 | J23: 0 | K23: 0 | L23: 0 | M23: 0 | N23: 0 | O23: 0 | P23: 0 | Q23: 0 | R23: 0 | S23: 0 | T23: 0 | U23: 0 | V23: 0
A24: Biomass Other | B24: GWh | C24: 0 | D24: 0 | E24: 0 | F24: 0 | G24: 0 | H24: 0 | I24: 0 | J24: 792.5 | K24: 1108 | L24: 648.7 | M24: 685.6 | N24: 685.9 | O24: 611.3 | P24: 1141.9611 | Q24: 960.22788 | R24: 1042.5623 | S24: 1036.6341 | T24: 919 | U24: 1072 | V24: 1006
A25: Biomass Gasification | B25: GWh
A26: Biomass Gasification with CCS | B26: GWh
A27: Biodiesel | B27: GWh
A28: Fuel Cell (Hydrogen) | B28: GWh
A29: Biogas | B29: GWh | C29: 0 | D29: 0 | E29: 0 | F29: 0 | G29: 0 | H29: 0 | I29: 0 | J29: 8 | K29: 6.9 | L29: 15.4 | M29: 44.7 | N29: 38.6 | O29: 111.9 | P29: 209.03886 | Q29: 175.77212 | R29: 190.84364 | S29: 189.75847 | T29: 545 | U29: 580 | V29: 699
A30: Battery | B30: GWh
A31: Others | B31: GWh
A32: Gas Engine | B32: GWh
A33: Waste to Energy | B33: GWh | C33: 0 | D33: 0 | E33: 0 | F33: 0 | G33: 0 | H33: 0 | I33: 0 | J33: 0 | K33: 0 | L33: 0 | M33: 0 | N33: 0 | O33: 0 | P33: 0 | Q33: 0 | R33: 0 | S33: 0 | T33: 0 | U33: 0 | V33: 0
A34: Total | B34: GWh | C34: 93027 | D34: 99526 | E34: 106225 | F34: 113820 | G34: 116315 | H34: 116957 | I34: 122123 | J34: 131200.7 | K34: 135688.4 | L34: 142141 | M34: 143287.5 | N34: 152233 | O34: 157418.5 | P34: 170576 | Q34: 178492 | R34: 174003.85 | S34: 178661.33 | T34: 192124 | U34: 201267 | V34: 207682

Sheet Laos_HP
A1: Technology | B1: Unit | C1: 2005 | D1: 2006 | E1: 2007 | F1: 2008 | G1: 2009 | H1: 2010 | I1: 2011 | J1: 2012 | K1: 2013 | L1: 2014 | M1: 2015 | N1: 2016 | O1: 2017 | P1: 2018 | Q1: 2019 | R1: 2020 | S1: 2021 | T1: 2022 | U1: 2023 | V1: 2024
A2: Coal Subcritical | B2: GWh | C2: 0 | D2: 0 | E2: 0 | F2: 0 | G2: 0 | H2: 0 | I2: 0 | J2: 0 | K2: 0 | L2: 0 | M2: 2245.5 | N2: 7961.9 | O2: 10927.2 | P2: 13655.817 | Q2: 12958.612 | R2: 12900.652 | S2: 11881 | T2: 12179 | U2: 12179 | V2: 12366.501
A3: Coal Supercritical | B3: GWh | C3: 0 | D3: 0 | E3: 0 | F3: 0 | G3: 0 | H3: 0 | I3: 0 | J3: 0 | K3: 0 | L3: 0 | M3: 0 | N3: 0 | O3: 0 | P3: 0 | Q3: 0 | R3: 0 | S3: 0 | T3: 0 | U3: 0 | V3: 0
A4: Coal Ultrasupercritical (USC) | B4: GWh | C4: 0 | D4: 0 | E4: 0 | F4: 0 | G4: 0 | H4: 0 | I4: 0 | J4: 0 | K4: 0 | L4: 0 | M4: 0 | N4: 0 | O4: 0 | P4: 0 | Q4: 0 | R4: 0 | S4: 0 | T4: 0 | U4: 0 | V4: 0
A5: Coal with CCS | B5: GWh
A6: Coal based IGCC | B6: GWh
A7: Coal based IGCC with CCS | B7: GWh
A8: Oil based Gas Turbine | B8: GWh
A9: Diesel Oil | B9: GWh | C9: 0 | D9: 0 | E9: 0 | F9: 0 | G9: 0 | H9: 0 | I9: 0 | J9: 0 | K9: 0 | L9: 0 | M9: 0 | N9: 0 | O9: 0 | P9: 0 | Q9: 0 | R9: 0 | S9: 0 | T9: 0 | U9: 0 | V9: 0
A10: Fuel Oil (Heavy Oil) | B10: GWh
A11: Other IGCC | B11: GWh
A12: Natural gas based Gas Turbine | B12: GWh
A13: Natural gas based IGCC | B13: GWh
A14: Combined Cycle Gas Turbine | B14: GWh | C14: 0 | D14: 0 | E14: 0 | F14: 0 | G14: 0 | H14: 0 | I14: 0 | J14: 0 | K14: 0 | L14: 0 | M14: 0 | N14: 0 | O14: 0 | P14: 0 | Q14: 0 | R14: 0 | S14: 0 | T14: 0 | U14: 0 | V14: 0
A15: Large Hydro | B15: GWh | C15: 3510 | D15: 3595.8 | E15: 3373.6 | F15: 3717 | G15: 3384.3 | H15: 8449.01 | I15: 12980.1 | J15: 12760.1 | K15: 15506.5 | L15: 15633.3 | M15: 14252 | N15: 17348.5 | O15: 20361.4 | P15: 22998.909 | Q15: 20140.378 | R15: 29089.748 | S15: 32917 | T15: 38736 | U15: 37248.641 | V15: 40424.543
A16: Small Hydro | B16: GWh
A17: Pumped Hydro Storage | B17: GWh
A18: Nuclear | B18: GWh
A19: Geothermal | B19: GWh | C19: 0 | D19: 0 | E19: 0 | F19: 0 | G19: 0 | H19: 0 | I19: 0 | J19: 0 | K19: 0 | L19: 0 | M19: 0 | N19: 0 | O19: 0 | P19: 0 | Q19: 0 | R19: 0 | S19: 0 | T19: 0 | U19: 0 | V19: 0
A20: Solar PV | B20: GWh | C20: 0.41 | D20: 0.41 | E20: 0.41 | F20: 0.41 | G20: 0.57 | H20: 0.66 | I20: 0.64 | J20: 0.7 | K20: 0.82 | L20: 0.83 | M20: 1.14 | N20: 1.47 | O20: 8.98 | P20: 59.819507 | Q20: 41.32 | R20: 61.578079 | S20: 67 | T20: 79 | U20: 95.825338 | V20: 114.15641
A21: Solar Thermal | B21: GWh
A22: Ocean | B22: GWh
A23: Wind Turbine | B23: GWh | C23: 0 | D23: 0 | E23: 0 | F23: 0 | G23: 0 | H23: 0 | I23: 0 | J23: 0 | K23: 0 | L23: 0 | M23: 0 | N23: 0 | O23: 0 | P23: 0 | Q23: 0 | R23: 0 | S23: 0 | T23: 0 | U23: 0 | V23: 0
A24: Biomass Other | B24: GWh | C24: 0 | D24: 0 | E24: 0 | F24: 0 | G24: 0 | H24: 0 | I24: 0 | J24: 0 | K24: 5.4 | L24: 5.2 | M24: 3.56 | N24: 4.73 | O24: 26.16 | P24: 46.836735 | Q24: 48.265306 | R24: 58.178112 | S24: 48.7 | T24: 36 | U24: 27.589677 | V24: 39.442901
A25: Biomass Gasification | B25: GWh
A26: Biomass Gasification with CCS | B26: GWh
A27: Biodiesel | B27: GWh
A28: Fuel Cell (Hydrogen) | B28: GWh
A29: Biogas | B29: GWh | C29: 0 | D29: 0 | E29: 0 | F29: 0 | G29: 0 | H29: 0 | I29: 0 | J29: 0 | K29: 0 | L29: 0 | M29: 0 | N29: 0 | O29: 0 | P29: 0 | Q29: 0 | R29: 0 | S29: 0 | T29: 0 | U29: 0 | V29: 0
A30: Battery | B30: GWh
A31: Others | B31: GWh
A32: Total | B32: GWh | C32: 3510.41 | D32: 3596.21 | E32: 3374.01 | F32: 3717.41 | G32: 3384.87 | H32: 8449.67 | I32: 12980.74 | J32: 12760.8 | K32: 15512.72 | L32: 15639.33 | M32: 16502.2 | N32: 25316.6 | O32: 31323.74 | P32: 36761.382 | Q32: 33188.575 | R32: 42110.156 | S32: 44913.7 | T32: 51030 | U32: 49551.056 | V32: 52944.644

Sheet Indonesia_HP
A1: Technology | B1: Unit | C1: 2005 | D1: 2006 | E1: 2007 | F1: 2008 | G1: 2009 | H1: 2010 | I1: 2011 | J1: 2012 | K1: 2013 | L1: 2014 | M1: 2015 | N1: 2016 | O1: 2017 | P1: 2018 | Q1: 2019 | R1: 2020 | S1: 2021 | T1: 2022 | U1: 2023 | V1: 2024
A2: Coal Subcritical | B2: GWh | C2: 60864 | D2: 68103 | E2: 74269 | F2: 72680 | G2: 75804 | H2: 76392 | I2: 88815 | J2: 101552 | K2: 110888 | L2: 119071 | M2: 129416 | N2: 128695 | O2: 134538 | P2: 110035 | Q2: 119520 | R2: 113335 | S2: 113488 | T2: 114728 | U2: 112035 | V2: 114158
A3: Coal Supercritical | B3: GWh | C3: 0 | D3: 0 | E3: 0 | F3: 0 | G3: 0 | H3: 0 | I3: 0 | J3: 8175 | K3: 7311 | L3: 7419 | M3: 7383 | N3: 12978 | O3: 18129 | P3: 49978 | Q3: 54973 | R3: 67534 | S3: 76196 | T3: 90580 | U3: 104742 | V3: 114276
A4: Coal Ultrasupercritical (USC) | B4: GWh | C4: 0 | D4: 0 | E4: 0 | F4: 0 | G4: 0 | H4: 0 | I4: 0 | J4: 0 | K4: 0 | L4: 0 | M4: 0 | N4: 0 | O4: 0 | P4: 0 | Q4: 0 | R4: 0 | S4: 0 | T4: 0 | U4: 0 | V4: 0
A5: Coal with CCS | B5: GWh | P5: 0 | Q5: 0 | R5: 0 | S5: 0 | T5: 0 | U5: 0 | V5: 0
A6: Coal based IGCC | B6: GWh | P6: 0 | Q6: 0 | R6: 0 | S6: 0 | T6: 0 | U6: 0 | V6: 0
A7: Coal based IGCC with CCS | B7: GWh | P7: 0 | Q7: 0 | R7: 0 | S7: 0 | T7: 0 | U7: 0 | V7: 0
A8: Oil based Gas Turbine | B8: GWh | P8: 0 | Q8: 0 | R8: 0 | S8: 0 | T8: 0 | U8: 0 | V8: 0
A9: Diesel Oil | B9: GWh | C9: 9117 | D9: 9173 | E9: 8961 | F9: 10640 | G9: 10825 | H9: 12294 | I9: 16475 | J9: 19192 | K9: 19307 | L9: 22280 | M9: 19492 | N9: 19708 | O9: 18563 | P9: 17429 | Q9: 10456 | R9: 6730 | S9: 6423 | T9: 6080 | U9: 6482 | V9: 7037
A10: Fuel Oil (Heavy Oil) | B10: GWh | C10: 0 | D10: 0 | E10: 0 | F10: 0 | G10: 0 | H10: 0 | I10: 0 | J10: 0 | K10: 0 | L10: 0 | M10: 0 | N10: 0 | O10: 0 | P10: 0 | Q10: 0 | R10: 0 | S10: 0 | T10: 0 | U10: 0 | V10: 0
A11: Other IGCC | B11: GWh | P11: 0 | Q11: 0 | R11: 0 | S11: 0 | T11: 0 | U11: 0 | V11: 0
A12: Natural gas based Gas Turbine | B12: GWh | C12: 6412 | D12: 5818 | E12: 6662 | F12: 6957 | G12: 10343 | H12: 10884 | I12: 11664 | J12: 10001 | K12: 10487 | L12: 10712 | M12: 7997 | N12: 6512 | O12: 7119 | P12: 9957 | Q12: 9144 | R12: 6495 | S12: 7212 | T12: 6566 | U12: 5321 | V12: 6650
A13: Natural gas based IGCC | B13: GWh | P13: 0 | Q13: 0 | R13: 0 | S13: 0 | T13: 0 | U13: 0 | V13: 0
A14: Combined Cycle Gas Turbine | B14: GWh | C14: 33838 | D14: 33734 | E14: 34120 | F14: 39322 | G14: 39141 | H14: 43324 | I14: 44589 | J14: 39088 | K14: 41431 | L14: 43781 | M14: 44646 | N14: 48208 | O14: 44173 | P14: 43963 | Q14: 43154 | R14: 34143 | S14: 37975 | T14: 38475 | U14: 43614 | V14: 47699
A15: Large Hydro | B15: GWh | C15: 10725 | D15: 9623 | E15: 11286 | F15: 11528 | G15: 11384 | H15: 17456 | I15: 12419 | J15: 12799 | K15: 16923 | L15: 15161 | M15: 13741 | N15: 18677 | O15: 18632 | P15: 21613 | Q15: 21125 | R15: 24289 | S15: 24578 | T15: 27161 | U15: 24590 | V15: 27138
A16: Small Hydro | B16: GWh | C16: 0 | D16: 0 | E16: 0 | F16: 0 | G16: 0 | H16: 0 | I16: 0 | J16: 0 | K16: 0 | L16: 0 | M16: 0 | N16: 0 | O16: 0 | P16: 24 | Q16: 36 | R16: 36 | S16: 119 | T16: 134 | U16: 0 | V16: 152
A17: Pumped Hydro Storage | B17: GWh | P17: 0 | Q17: 0 | R17: 0 | S17: 0 | T17: 0 | U17: 0 | V17: 0
A18: Nuclear | B18: GWh | P18: 0 | Q18: 0 | R18: 0 | S18: 0 | T18: 0 | U18: 0 | V18: 0
A19: Geothermal | B19: GWh | C19: 6604 | D19: 6658 | E19: 7021 | F19: 8309 | G19: 9295 | H19: 9357 | I19: 9371 | J19: 9416 | K19: 9414 | L19: 10039 | M19: 10047 | N19: 10656 | O19: 12764 | P19: 14019 | Q19: 14100 | R19: 15563 | S19: 15899 | T19: 16677 | U19: 16936 | V19: 16763
A20: Solar PV | B20: GWh | C20: 0 | D20: 0 | E20: 0 | F20: 0 | G20: 0 | H20: 0.517 | I20: 0.773 | J20: 3.012 | K20: 5.497 | L20: 6.814 | M20: 5.277 | N20: 21.092 | O20: 29.05 | P20: 90.27 | Q20: 118.28 | R20: 170.97 | S20: 192.62 | T20: 443.73 | U20: 712.87 | V20: 1350.98
A21: Solar Thermal | B21: GWh | P21: 0 | Q21: 0 | R21: 0 | S21: 0 | T21: 0 | U21: 0 | V21: 0
A22: Ocean | B22: GWh | P22: 0 | Q22: 0 | R22: 0 | S22: 0 | T22: 0 | U22: 0 | V22: 0
A23: Wind Turbine | B23: GWh | C23: 0 | D23: 0 | E23: 0.02 | F23: 0.3 | G23: 3.7 | H23: 3.63 | I23: 4.7 | J23: 4.6 | K23: 0.1 | L23: 0 | M23: 3.7 | N23: 5.7 | O23: 0 | P23: 190 | Q23: 484 | R23: 475 | S23: 437 | T23: 356 | U23: 481 | V23: 467
A24: Biomass Other | B24: GWh | C24: 0 | D24: 0 | E24: 0 | F24: 0 | G24: 0 | H24: 0 | I24: 0 | J24: 0 | K24: 0 | L24: 0 | M24: 0 | N24: 0 | O24: 0 | P24: 15706 | Q24: 15283 | R24: 12984 | S24: 15254 | T24: 20442 | U24: 24326 | V24: 23938.01
A25: Biomass Gasification | B25: GWh | P25: 0 | Q25: 0 | R25: 0 | S25: 0 | T25: 0 | U25: 0 | V25: 0
A26: Biomass Gasification with CCS | B26: GWh | P26: 0 | Q26: 0 | R26: 0 | S26: 0 | T26: 0 | U26: 0 | V26: 0
A27: Biodiesel | B27: GWh | P27: 0 | Q27: 0 | R27: 0 | S27: 0 | T27: 0 | U27: 0 | V27: 0
A28: Fuel Cell (Hydrogen) | B28: GWh | P28: 0 | Q28: 0 | R28: 0 | S28: 0 | T28: 0 | U28: 0 | V28: 0
A29: Biogas | B29: GWh | C29: 0 | D29: 0 | E29: 0 | F29: 0 | G29: 0 | H29: 0 | I29: 0 | J29: 0 | K29: 0 | L29: 0 | M29: 0 | N29: 0 | O29: 0 | P29: 573 | Q29: 618 | R29: 799 | S29: 940 | T29: 1044 | U29: 1012 | V29: 1114
A30: Battery | B30: GWh | P30: 0 | Q30: 0 | R30: 0 | S30: 0 | T30: 0 | U30: 0 | V30: 0
A31: Others | B31: GWh | P31: 0 | Q31: 0 | R31: 0 | S31: 0 | T31: 0 | U31: 0 | V31: 0
A32: Gas Engine | B32: GWh | C32: 0 | D32: 0 | E32: 121 | F32: 0 | G32: 0 | H32: 74 | I32: 48 | J32: 55 | K32: 382 | L32: 51 | M32: 1233 | N32: 2451 | O32: 82 | P32: 198 | Q32: 6417 | R32: 9259 | S32: 10353 | T32: 10806 | U32: 10295 | V32: 10748
A33: Waste to Energy | B33: GWh | C33: 0 | D33: 0 | E33: 0 | F33: 0 | G33: 0 | H33: 0 | I33: 30.9 | J33: 30.9 | K33: 40.8 | L33: 35.5 | M33: 19.4 | N33: 5.9 | O33: 590.4 | P33: 0 | Q33: 21 | R33: 17 | S33: 11 | T33: 44 | U33: 61 | V33: 60
A34: Total | B34: GWh | C34: 127560 | D34: 133109 | E34: 142440.02 | F34: 149436.3 | G34: 156795.7 | H34: 169785.15 | I34: 183417.37 | J34: 200316.51 | K34: 216189.4 | L34: 228556.31 | M34: 233983.38 | N34: 247917.69 | O34: 254619.45 | P34: 283775.27 | Q34: 295449.28 | R34: 291829.97 | S34: 309077.62 | T34: 333536.73 | U34: 350607.87 | V34: 371550.99

Sheet Cambodia_HP
A1: Technology | B1: Unit | C1: 2005 | D1: 2006 | E1: 2007 | F1: 2008 | G1: 2009 | H1: 2010 | I1: 2011 | J1: 2012 | K1: 2013 | L1: 2014 | M1: 2015 | N1: 2016 | O1: 2017 | P1: 2018 | Q1: 2019 | R1: 2020 | S1: 2021 | T1: 2022 | U1: 2023 | V1: 2024
A2: Coal Subcritical | B2: GWh | C2: 0 | D2: 0 | E2: 0 | F2: 23.36 | G2: 28.03 | H2: 32.08 | I2: 46.5 | J2: 37.42 | K2: 168.75 | L2: 863.02 | M2: 2210.14 | N2: 2551.17 | O2: 3569.01 | P2: 3362 | Q2: 4107 | R2: 4311 | S2: 3455.6 | T2: 3664.67 | U2: 7665.13 | V2: 9208.88
A3: Coal Supercritical | B3: GWh | C3: 0 | D3: 0 | E3: 0 | F3: 0 | G3: 0 | H3: 0 | I3: 0 | J3: 0 | K3: 0 | L3: 0 | M3: 0 | N3: 0 | O3: 0 | P3: 0 | Q3: 0 | R3: 0 | S3: 0 | T3: 0
A4: Coal Ultrasupercritical (USC) | B4: GWh | C4: 0 | D4: 0 | E4: 0 | F4: 0 | G4: 0 | H4: 0 | I4: 0 | J4: 0 | K4: 0 | L4: 0 | M4: 0 | N4: 0 | O4: 0 | P4: 0 | Q4: 0 | R4: 0 | S4: 0 | T4: 0
A5: Coal with CCS | B5: GWh
A6: Coal based IGCC | B6: GWh
A7: Coal based IGCC with CCS | B7: GWh
A8: Oil based Gas Turbine | B8: GWh
A9: Diesel Oil | B9: GWh | C9: 21 | D9: 24 | E9: 36 | F9: 38 | G9: 42 | H9: 41 | I9: 38 | J9: 40 | K9: 28 | L9: 28 | M9: 94 | N9: 16 | O9: 10 | P9: 0 | Q9: 0 | R9: 0 | S9: 0 | T9: 0
A10: Fuel Oil (Heavy Oil) | B10: GWh | C10: 815 | D10: 1011 | E10: 1258 | F10: 1372 | G10: 1111 | H10: 858 | I10: 871 | J10: 816 | K10: 551 | L10: 299 | M10: 118 | N10: 362 | O10: 381 | P10: 302 | Q10: 739 | R10: 451 | S10: 553.64 | T10: 351.14 | U10: 53.28 | V10: 532.42
A11: Other IGCC | B11: GWh
A12: Natural gas based Gas Turbine | B12: GWh
A13: Natural gas based IGCC | B13: GWh
A14: Combined Cycle Gas Turbine | B14: GWh
A15: Large Hydro | B15: GWh | C15: 43.54 | D15: 50.61 | E15: 49.71 | F15: 46.28 | G15: 47.43 | H15: 31.73 | I15: 51.52 | J15: 517.37 | K15: 1015.54 | L15: 1851.6 | M15: 1988.38 | N15: 2619.11 | O15: 2711.14 | P15: 4832 | Q15: 4106 | R15: 3937 | S15: 5043.94 | T15: 5557.55 | U15: 7333.41 | V15: 7227.78
A16: Small Hydro | B16: GWh
A17: Pumped Hydro Storage | B17: GWh
A18: Nuclear | B18: GWh
A19: Geothermal | B19: GWh | C19: 0 | D19: 0 | E19: 0 | F19: 0 | G19: 0 | H19: 0 | I19: 0 | J19: 0 | K19: 0 | L19: 0 | M19: 0 | N19: 0 | O19: 0 | P19: 0 | Q19: 0 | R19: 0 | S19: 0 | T19: 0
A20: Solar PV | B20: GWh | C20: 0 | D20: 0 | E20: 0 | F20: 0 | G20: 0 | H20: 0 | I20: 0 | J20: 0 | K20: 0 | L20: 0 | M20: 0 | N20: 0 | O20: 4.66 | P20: 16 | Q20: 92 | R20: 290 | S20: 609.96 | T20: 687.87 | U20: 805.06 | V20: 1278.96
A21: Solar Thermal | B21: GWh
A22: Ocean | B22: GWh
A23: Wind Turbine | B23: GWh | C23: 0 | D23: 0 | E23: 0 | F23: 0 | G23: 0 | H23: 0 | I23: 0 | J23: 0 | K23: 0 | L23: 0 | M23: 0 | N23: 0 | O23: 0 | P23: 0 | Q23: 0 | R23: 0 | S23: 0 | T23: 0
A24: Biomass Other | B24: GWh | C24: 0.12 | D24: 1.68 | E24: 5.25 | F24: 4.53 | G24: 6.49 | H24: 5.82 | I24: 11.91 | J24: 11.75 | K24: 6.68 | L24: 16.79 | M24: 38.04 | N24: 43.35 | O24: 51.87 | P24: 64 | Q24: 92 | R24: 66 | S24: 49.63 | T24: 51.63 | U24: 62.93 | V24: 66.66
A25: Biomass Gasification | B25: GWh
A26: Biomass Gasification with CCS | B26: GWh
A27: Biodiesel | B27: GWh
A28: Fuel Cell (Hydrogen) | B28: GWh
A29: Biogas | B29: GWh
A30: Battery | B30: GWh
A31: Others | B31: GWh
A32: Gas Engine | B32: GWh
A33: Waste to Energy | B33: GWh
A34: Total | B34: GWh | C34: 879.66 | D34: 1087.29 | E34: 1348.96 | F34: 1484.17 | G34: 1234.95 | H34: 968.63 | I34: 1018.93 | J34: 1422.54 | K34: 1769.97 | L34: 3058.41 | M34: 4448.56 | N34: 5591.63 | O34: 6727.68 | P34: 8576 | Q34: 9136 | R34: 9055 | S34: 9712.77 | T34: 10312.86 | U34: 15919.81 | V34: 18314.7

Sheet Brunei_HP
A1: Technology | B1: Unit | C1: 2005 | D1: 2006 | E1: 2007 | F1: 2008 | G1: 2009 | H1: 2010 | I1: 2011 | J1: 2012 | K1: 2013 | L1: 2014 | M1: 2015 | N1: 2016 | O1: 2017 | P1: 2018 | Q1: 2019 | R1: 2020 | S1: 2021 | T1: 2022 | U1: 2023 | V1: 2024
A2: Coal Subcritical | B2: GWh
A3: Coal Supercritical | B3: GWh
A4: Coal Ultrasupercritical (USC) | B4: GWh
A5: Coal with CCS | B5: GWh
A6: Coal based IGCC | B6: GWh | Q6: 484.0827 | R6: 914.47981 | S6: 1241.882 | T6: 1207.644 | U6: 1144.308 | V6: 1190.072
A7: Coal based IGCC with CCS | B7: GWh
A8: Oil based Gas Turbine | B8: GWh
A9: Diesel Oil | B9: GWh | C9: 28.6 | D9: 30.6 | E9: 32.8 | F9: 33.3 | G9: 36.6 | H9: 37.9 | I9: 37.4 | J9: 37.8 | K9: 38.1 | L9: 39.6 | M9: 42.4 | N9: 45.2 | O9: 45.5 | P9: 46.875082 | Q9: 48.8701 | R9: 39.903941 | S9: 36.385892 | T9: 45.768235 | U9: 41.724482 | V9: 42.494313
A10: Fuel Oil (Heavy Oil) | B10: GWh
A11: Other IGCC | B11: GWh
A12: Natural gas based Gas Turbine | B12: GWh | C12: 2491.26 | D12: 2592.23 | E12: 2656.1 | F12: 2700.989 | G12: 2739.3 | H12: 2715.5 | I12: 2483.5 | J12: 2582.9 | K12: 2684.9 | L12: 2749.8 | M12: 2845.4 | N12: 2836.1 | O12: 2721.936 | P12: 2664.3833 | Q12: 2693.411 | R12: 2654.898 | S12: 2710.998 | T12: 2491.5991 | U12: 2581.808 | V12: 2798.774
A13: Natural gas based IGCC | B13: GWh
A14: Combined Cycle Gas Turbine | B14: GWh | C14: 618.6 | D14: 659.4 | E14: 705.9 | F14: 693 | G14: 850.5 | H14: 1038.8 | I14: 1202.1 | J14: 1307.9 | K14: 1238.8 | L14: 1265.2 | M14: 1311 | N14: 1388.6 | O14: 1388.378 | P14: 1580.747 | Q14: 1706.877 | R14: 1813.802 | S14: 1706.045 | T14: 1852.153 | U14: 1837.731 | V14: 1776.212
A15: Large Hydro | B15: GWh
A16: Small Hydro | B16: GWh
A17: Pumped Hydro Storage | B17: GWh
A18: Nuclear | B18: GWh
A19: Geothermal | B19: GWh
A20: Solar PV | B20: GWh | M20: 1.29343 | N20: 1.1 | O20: 1.5453633 | P20: 1.5690217 | Q20: 1.0583202 | R20: 0.9831022 | S20: 4.4298973 | T20: 5.0871643 | U20: 5.5786029 | V20: 4.8223759
A21: Solar Thermal | B21: GWh
A22: Ocean | B22: GWh
A23: Wind Turbine | B23: GWh
A24: Biomass Other | B24: GWh
A25: Biomass Gasification | B25: GWh
A26: Biomass Gasification with CCS | B26: GWh
A27: Biodiesel | B27: GWh
A28: Fuel Cell (Hydrogen) | B28: GWh
A29: Biogas | B29: GWh
A30: Battery | B30: GWh
A31: Others | B31: GWh
A32: Gas Engine | B32: GWh
A33: Waste to Energy | B33: GWh
A34: Total | B34: GWh | C34: 3138.46 | D34: 3282.23 | E34: 3394.8 | F34: 3427.289 | G34: 3626.4 | H34: 3792.2 | I34: 3723 | J34: 3928.6 | K34: 3961.8 | L34: 4054.6 | M34: 4200.0934 | N34: 4271 | O34: 4157.3594 | P34: 4293.5744 | Q34: 4934.2991 | R34: 5424.0669 | S34: 5699.7408 | T34: 5602.2515 | U34: 5611.1501 | V34: 5812.3747

Sheet LEAP
E1: Area: | F1: aeo9_v0.34_YY | G1: Ver: | H1: 2
A3: BranchID | B3: VariableID | C3: ScenarioID | D3: RegionID | E3: Branch Path | F3: Variable | G3: Scenario | H3: Region | I3: Scale | J3: Units | K3: Per... | L3: Method | M3: 2005 | N3: 2006 | O3: 2007 | P3: 2008 | Q3: 2009 | R3: 2010 | S3: 2011 | T3: 2012 | U3: 2013 | V3: 2014 | W3: 2015 | X3: 2016 | Y3: 2017 | Z3: 2018 | AA3: 2019 | AB3: 2020 | AC3: 2021 | AD3: 2022 | AE3: 2023 | AF3: 2024
A4: 2720 | B4: 2148 | C4: 1 | D4: 15 | E4: Transformation\Centralized Electricity Generation\Processes\Coal Subcritical | F4: Historical Production | G4: Current Accounts | H4: Brunei | J4: Gigawatt-Hour | L4: Interp | M4: 0 | N4: 0 | O4: 0 | P4: 0 | Q4: 0 | R4: 0 | S4: 0 | T4: 0 | U4: 0 | V4: 0 | W4: 0 | X4: 0 | Y4: 0 | Z4: 0 | AA4: 0 | AB4: 0 | AC4: 0 | AD4: 0 | AE4: 0 | AF4: 0
A5: 2720 | B5: 1593 | C5: 1 | D5: 15 | E5: Transformation\Centralized Electricity Generation\Processes\Coal Subcritical | F5: Existing Capacity | G5: Current Accounts | H5: Brunei | J5: MW | L5: Interp | M5: 0 | N5: 0 | O5: 0 | P5: 0 | Q5: 0 | R5: 0 | S5: 0 | T5: 0 | U5: 0 | V5: 0 | W5: 0 | X5: 0 | Y5: 0 | Z5: 0 | AA5: 0 | AB5: 0 | AC5: 0 | AD5: 0 | AE5: 0 | AF5: 0
A6: 2720 | B6: 2148 | C6: 1 | D6: 6 | E6: Transformation\Centralized Electricity Generation\Processes\Coal Subcritical | F6: Historical Production | G6: Current Accounts | H6: Cambodia | J6: Gigawatt-Hour | L6: Interp | M6: 0 | N6: 0 | O6: 0 | P6: 23.36 | Q6: 28.03 | R6: 32.08 | S6: 46.5 | T6: 37.42 | U6: 168.75 | V6: 863.02 | W6: 2210.14 | X6: 2551.17 | Y6: 3569.01 | Z6: 3362 | AA6: 4107 | AB6: 4311 | AC6: 3455.6 | AD6: 3664.67 | AE6: 7665.1 | AF6: 8895.1
A7: 2720 | B7: 1593 | C7: 1 | D7: 6 | E7: Transformation\Centralized Electricity Generation\Processes\Coal Subcritical | F7: Existing Capacity | G7: Current Accounts | H7: Cambodia | J7: MW | L7: Interp | M7: 0 | N7: 0 | O7: 0 | P7: 13 | Q7: 13 | R7: 13 | S7: 13 | T7: 13 | U7: 113 | V7: 268 | W7: 403 | X7: 429.2 | Y7: 538 | Z7: 551 | AA7: 709 | AB7: 675 | AC7: 675 | AD7: 1025 | AE7: 1300 | AF7: 1300
A8: 2720 | B8: 2148 | C8: 1 | D8: 1 | E8: Transformation\Centralized Electricity Generation\Processes\Coal Subcritical | F8: Historical Production | G8: Current Accounts | H8: Indonesia | J8: Gigawatt-Hour | L8: Interp | M8: 60864 | N8: 68103 | O8: 74269 | P8: 72680 | Q8: 75804 | R8: 76392 | S8: 88815 | T8: 101552 | U8: 110888 | V8: 119071 | W8: 129416 | X8: 128695 | Y8: 134538 | Z8: 110035 | AA8: 119520 | AB8: 113335 | AC8: 113762 | AD8: 114728 | AE8: 112035 | AF8: 114158
A9: 2720 | B9: 1593 | C9: 1 | D9: 1 | E9: Transformation\Centralized Electricity Generation\Processes\Coal Subcritical | F9: Existing Capacity | G9: Current Accounts | H9: Indonesia | J9: MW | L9: Interp | M9: 9750 | N9: 11170 | O9: 12014 | P9: 12294 | Q9: 12594 | R9: 12981.5 | S9: 16359 | T9: 16805 | U9: 20868.53 | V9: 22160.23 | W9: 24285.73 | X9: 24388.23 | Y9: 23396.2 | Z9: 28178.17 | AA9: 31328.17 | AB9: 33258.86 | AC9: 33627.36 | AD9: 42635.26 | AE9: 49756.37 | AF9: 54338.84
A10: 2720 | B10: 2148 | C10: 1 | D10: 13 | E10: Transformation\Centralized Electricity Generation\Processes\Coal Subcritical | F10: Historical Production | G10: Current Accounts | H10: Laos | J10: Gigawatt-Hour | L10: Interp | M10: 0 | N10: 0 | O10: 0 | P10: 0 | Q10: 0 | R10: 0 | S10: 0 | T10: 0 | U10: 0 | V10: 0 | W10: 2246 | X10: 7962 | Y10: 10927 | Z10: 13656 | AA10: 12959 | AB10: 12901 | AC10: 11881 | AD10: 12179 | AE10: 12179 | AF10: 12367
A11: 2720 | B11: 1593 | C11: 1 | D11: 13 | E11: Transformation\Centralized Electricity Generation\Processes\Coal Subcritical | F11: Existing Capacity | G11: Current Accounts | H11: Laos | J11: MW | L11: Interp | M11: 0 | N11: 0 | O11: 0 | P11: 0 | Q11: 0 | R11: 0 | S11: 0 | T11: 0 | U11: 0 | V11: 0 | W11: 1878 | X11: 1878 | Y11: 1878 | Z11: 1878 | AA11: 1878 | AB11: 1878 | AC11: 1878 | AD11: 1878 | AE11: 1878 | AF11: 1878
A12: 2720 | B12: 2148 | C12: 1 | D12: 17 | E12: Transformation\Centralized Electricity Generation\Processes\Coal Subcritical | F12: Historical Production | G12: Current Accounts | H12: Malaysia | J12: Gigawatt-Hour | L12: Interp | M12: 24228 | N12: 26527 | O12: 32932 | P12: 36585 | Q12: 44329 | R12: 47595 | S12: 48932 | T12: 52584 | U12: 50747 | V12: 50536 | W12: 52004 | X12: 51853 | Y12: 51643 | Z12: 61828.8 | AA12: 61128.8 | AB12: 71100.29 | AC12: 67867.33 | AD12: 65777.6 | AE12: 68496 | AF12: 71604
A13: 2720 | B13: 1593 | C13: 1 | D13: 17 | E13: Transformation\Centralized Electricity Generation\Processes\Coal Subcritical | F13: Existing Capacity | G13: Current Accounts | H13: Malaysia | J13: MW | L13: Interp | M13: 3900 | N13: 4610 | O13: 6010 | P13: 6145 | Q13: 6755 | R13: 7650 | S13: 7680 | T13: 7680 | U13: 7680 | V13: 7680 | W13: 7536 | X13: 8536 | Y13: 8536 | Z13: 8628.27 | AA13: 10397.63 | AB13: 10752.15 | AC13: 10563.56 | AD13: 10658.29 | AE13: 10756.8 | AF13: 10756.8
A14: 2720 | B14: 2148 | C14: 1 | D14: 12 | E14: Transformation\Centralized Electricity Generation\Processes\Coal Subcritical | F14: Historical Production | G14: Current Accounts | H14: Myanmar | J14: Gigawatt-Hour | L14: Interp | M14: 232.66 | N14: 382.21 | O14: 401.82 | P14: 198.39 | Q14: 228.95 | R14: 365.91 | S14: 292.13 | T14: 241.71 | U14: 125.6 | V14: 66.1 | W14: 0 | X14: 9.3 | Y14: 438.67 | Z14: 561.69 | AA14: 692.96 | AB14: 554.12 | AC14: 356.13 | AD14: 705.34 | AE14: 759.46 | AF14: 632.79
A15: 2720 | B15: 1593 | C15: 1 | D15: 12 | E15: Transformation\Centralized Electricity Generation\Processes\Coal Subcritical | F15: Existing Capacity | G15: Current Accounts | H15: Myanmar | J15: MW | L15: Interp | M15: 120 | N15: 120 | O15: 120 | P15: 120 | Q15: 120 | R15: 120 | S15: 120 | T15: 120 | U15: 120 | V15: 120 | W15: 120 | X15: 120 | Y15: 120 | Z15: 120 | AA15: 120 | AB15: 120 | AC15: 120 | AD15: 138 | AE15: 190 | AF15: 190
... A803: 14414 | B803: 1593 | C803: 1 | D803: 14 | E803: Transformation\Centralized Electricity Generation\Processes\Unmet Load | F803: Existing Capacity | G803: Current Accounts | H803: Vietnam | J803: MW | L803: Interp | M803: 0 | N803: 0 | O803: 0 | P803: 0 | Q803: 0 | R803: 0 | S803: 0 | T803: 0 | U803: 0 | V803: 0 | W803: 0 | X803: 0 | Y803: 0 | Z803: 0 | AA803: 0 | AB803: 0 | AC803: 0 | AD803: 0 | AE803: 0 | AF803: 0

Sheet Input_to_LEAP
A1: Country | B1: Variable | C1: Unit | D1: Branch Path | E1: {=_xlfn.SEQUENCE(,20,2005)} -> 2005 | F1: 2006 | G1: 2007 | H1: 2008 | I1: 2009 | J1: 2010 | K1: 2011 | L1: 2012 | M1: 2013 | N1: 2014 | O1: 2015 | P1: 2016 | Q1: 2017 | R1: 2018 | S1: 2019 | T1: 2020 | U1: 2021 | V1: 2022 | W1: 2023 | X1: 2024
A2: Brunei | B2: Existing Capacity | C2: =IF(B2="Existing Capacity", "MW", "GWh") -> MW | D2: {=_xlfn.LET(_xlpm.country,A2, _xlpm.table,INDIRECT(IF(B2="Existing Capacity",_xlpm.country,_xlpm.country&"_HP")), _xlpm.val,_xlfn._xlws.FILTER(_xlfn.HSTACK(leap[Branch Path],leap[[2005]:[2024]]),(leap[Region]=A2)*(leap[Variable]=B2)), _xlpm.fval,_xlfn._xlws.FILTER(_xlpm.val,_xlfn.BYROW(_xlfn.DROP(_xlpm.val,,1),_xleta.SUM)>0), _xlpm.fuel,_xlfn.TEXTAFTER(_xlfn.TAKE(_xlpm.fval,,1),"\",3), _xlpm.mapping,VLOOKUP(_xlpm.fuel,Mapping!$B$3:$L$42,MATCH(_xlpm.country,AMS,0)+1,0), _xlpm.id,_xlfn.MAP(MATCH(_xlpm.mapping,_xlfn.TAKE(_xlpm.table,,1),0),_xlfn.LAMBDA(_xlpm.x,IFERROR(_xlpm.x,30))), _xlpm.fuel_val,_xlfn.DROP(_xlfn.CHOOSEROWS(_xlpm.table,_xlpm.id),,2), _xlfn.HSTACK(_xlfn.TAKE(_xlpm.fval,,1),_xlpm.fuel_val))} -> Transformation\Centralized Electricity Generation\Processes\Coal IGCC | E2: 0 | F2: 0 | G2: 0 | H2: 0 | I2: 0 | J2: 0 | K2: 0 | L2: 0 | M2: 0 | N2: 0 | O2: 0 | P2: 0 | Q2: 0 | R2: 0 | S2: 254 | T2: 254 | U2: 254 | V2: 254 | W2: 254 | X2: 254 | AB2: {=_xlfn.UNIQUE(_xlfn.TEXTAFTER(_xlfn._xlws.FILTER(D:D,A:A="Malaysia"),"\",3))} -> Coal Subcritical
A3: {=_xlfn.TOCOL(IF(_xlfn.SEQUENCE(, ROWS(_xlfn.ANCHORARRAY(D2))-1)<=ROWS(_xlfn.ANCHORARRAY(D2))-1,A2,NA()))} -> Brunei | B3: {=_xlfn.TOCOL(IF(_xlfn.SEQUENCE(, ROWS(_xlfn.ANCHORARRAY(D2))-1)<=ROWS(_xlfn.ANCHORARRAY(D2))-1,B2,NA()))} -> Existing Capacity | C3: {=_xlfn.TOCOL(IF(_xlfn.SEQUENCE(, ROWS(_xlfn.ANCHORARRAY(D2))-1)<=ROWS(_xlfn.ANCHORARRAY(D2))-1,C2,NA()))} -> MW | D3: Transformation\Centralized Electricity Generation\Processes\Diesel | E3: 13.5 | F3: 13.5 | G3: 13.5 | H3: 13.5 | I3: 13.5 | J3: 15 | K3: 14 | L3: 14 | M3: 14 | N3: 14 | O3: 12 | P3: 12 | Q3: 12 | R3: 12 | S3: 12 | T3: 12 | U3: 15 | V3: 15 | W3: 15 | X3: 15 | AB3: Coal Ultrasupercritical
A4: Brunei | B4: Existing Capacity | C4: MW | D4: Transformation\Centralized Electricity Generation\Processes\Gas Turbine | E4: 567.43 | F4: 566.97 | G4: 566.59 | H4: 569.04 | I4: 569.71 | J4: 576.95 | K4: 583.95 | L4: 605.95 | M4: 607.49 | N4: 610.39 | O4: 613.99 | P4: 613.99 | Q4: 613.99 | R4: 613.73 | S4: 627.73 | T4: 627.73 | U4: 669.43 | V4: 669.43 | W4: 669.43 | X4: 669.43 | AB4: Diesel
A5: Brunei | B5: Existing Capacity | C5: MW | D5: Transformation\Centralized Electricity Generation\Processes\Gas Combined Cycle | E5: 180 | F5: 180 | G5: 296 | H5: 296 | I5: 296 | J5: 296 | K5: 296 | L5: 296 | M5: 296 | N5: 296 | O5: 296 | P5: 331 | Q5: 366 | R5: 366 | S5: 366 | T5: 366 | U5: 366 | V5: 366 | W5: 366 | X5: 366 | AB5: Gas Combined Cycle
A6: Brunei | B6: Existing Capacity | C6: MW | D6: Transformation\Centralized Electricity Generation\Processes\Solar PV | E6: 0 | F6: 0 | G6: 0 | H6: 0 | I6: 0 | J6: 1 | K6: 1 | L6: 1 | M6: 1 | N6: 1 | O6: 1 | P6: 1 | Q6: 1 | R6: 1.2 | S6: 1.2 | T6: 1.2 | U6: 4.5 | V6: 4.5 | W6: 4.5 | X6: 6.8 | AB6: Large Hydro
A7: Cambodia | B7: Existing Capacity | C7: =IF(B7="Existing Capacity", "MW", "GWh") -> MW | D7: {=_xlfn.LET(_xlpm.country,A7, _xlpm.table,INDIRECT(IF(B7="Existing Capacity",_xlpm.country,_xlpm.country&"_HP")), _xlpm.val,_xlfn._xlws.FILTER(_xlfn.HSTACK(leap[Branch Path],leap[[2005]:[2024]]),(leap[Region]=A7)*(leap[Variable]=B7)), _xlpm.fval,_xlfn._xlws.FILTER(_xlpm.val,_xlfn.BYROW(_xlfn.DROP(_xlpm.val,,1),_xleta.SUM)>0), _xlpm.fuel,_xlfn.TEXTAFTER(_xlfn.TAKE(_xlpm.fval,,1),"\",3), _xlpm.mapping,VLOOKUP(_xlpm.fuel,Mapping!$B$3:$L$42,MATCH(_xlpm.country,AMS,0)+1,0), _xlpm.id,_xlfn.MAP(MATCH(_xlpm.mapping,_xlfn.TAKE(_xlpm.table,,1),0),_xlfn.LAMBDA(_xlpm.x,IFERROR(_xlpm.x,30))), _xlpm.fuel_val,_xlfn.DROP(_xlfn.CHOOSEROWS(_xlpm.table,_xlpm.id),,2), _xlfn.HSTACK(_xlfn.TAKE(_xlpm.fval,,1),_xlpm.fuel_val))} -> Transformation\Centralized Electricity Generation\Processes\Coal Subcritical | E7: 0 | F7: 0 | G7: 0 | H7: 13 | I7: 13 | J7: 13 | K7: 13 | L7: 13 | M7: 113 | N7: 268 | O7: 403 | P7: 429.2 | Q7: 538 | R7: 551 | S7: 709 | T7: 675 | U7: 675 | V7: 1025 | W7: 1300 | X7: 1300 | AB7: Solar PV
